
Internal Server Error: datascadenza
Internal Server Error: datascadenza
Internal Server Error: datascadenza
Internal Server Error: datascadenza
Internal Server Error: can't compare datetime.datetime to datetime.date
Internal Server Error: '>' not supported between instances of 'str' and 'datetime.date'
Internal Server Error: '>' not supported between instances of 'str' and 'datetime.date'
Internal Server Error: can't compare datetime.datetime to datetime.date
Internal Server Error: can't compare datetime.datetime to datetime.date
Internal Server Error: strptime() argument 1 must be str, not datetime.date
Database Error: day is out of range for month
Internal Server Error in get_user_data: You must call `@jwt_required()` or `verify_jwt_in_request()` before using this method
Internal Server Error in get_user_data: You must call `@jwt_required()` or `verify_jwt_in_request()` before using this method
Exception on /api/utente/data [GET]
Traceback (most recent call last):
  File "/src/backend/app/__init__.py", line 34, in user_lookup_callback
    studente = session.query(Studente).filter_by(email=identity).one_or_none()
NameError: name 'session' is not defined

During handling of the above exception, another exception occurred:

Traceback (most recent call last):
  File "/usr/local/lib/python3.9/site-packages/flask/app.py", line 1511, in wsgi_app
    response = self.full_dispatch_request()
  File "/usr/local/lib/python3.9/site-packages/flask/app.py", line 919, in full_dispatch_request
    rv = self.handle_user_exception(e)
  File "/usr/local/lib/python3.9/site-packages/flask_cors/extension.py", line 176, in wrapped_function
    return cors_after_request(app.make_response(f(*args, **kwargs)))
  File "/usr/local/lib/python3.9/site-packages/flask/app.py", line 917, in full_dispatch_request
    rv = self.dispatch_request()
  File "/usr/local/lib/python3.9/site-packages/flask/app.py", line 902, in dispatch_request
    return self.ensure_sync(self.view_functions[rule.endpoint])(**view_args)  # type: ignore[no-any-return]
  File "/usr/local/lib/python3.9/site-packages/flask_jwt_extended/view_decorators.py", line 167, in decorator
    verify_jwt_in_request(
  File "/usr/local/lib/python3.9/site-packages/flask_jwt_extended/view_decorators.py", line 113, in verify_jwt_in_request
    g._jwt_extended_jwt_user = _load_user(jwt_header, jwt_data)
  File "/usr/local/lib/python3.9/site-packages/flask_jwt_extended/view_decorators.py", line 182, in _load_user
    user = user_lookup(jwt_header, jwt_data)
  File "/usr/local/lib/python3.9/site-packages/flask_jwt_extended/internal_utils.py", line 44, in user_lookup
    return jwt_manager._user_lookup_callback and jwt_manager._user_lookup_callback(
  File "/src/backend/app/__init__.py", line 60, in user_lookup_callback
    except SQLAlchemyError:
NameError: name 'SQLAlchemyError' is not defined
Internal Server Error: string indices must be integers
Internal Server Error: 'function' object has no attribute 'get'
Internal Server Error: string indices must be integers
Internal Server Error: string indices must be integers
Internal Server Error: string indices must be integers
Internal Server Error: string indices must be integers
Internal Server Error: string indices must be integers
